Workbook

Sheet Séances
A1: Semaine | B1: Cours en classe entière (3h/semaine) – progression décalée | C1: Jeudi 1h | D1: Vendredi 1ere heure | E1: Vendredi seconde heure | F1: Questions flashs | I1: Remarques | J1: Chapitre avant décalage | K1: Changement | L1: Notes du décalage | M1: Légende : texte bleu = séances planifiées et notes (à modifier) ; colonne K calculée ; lignes surlignées = chapitre modifié. Semaines passées recopiées de la capture.
A2: =DATE(2026,8,31) -> 46265 | B2: Ch1 – Généralités sur les fonctions | C2: Heure 1: Présentation. Q flash fonctions secondes https://coopmaths.fr/alea/?uuid=5622b&id=2F16-1&alea=b2B7&uuid=b92dc&id=2F11-flash1&alea=m6e5&uuid=d85c2&id=2F10-flash1&alea=Rsj0&uuid=966a6&id=2F12-flash1&alea=Ukem&uuid=0e1c6&id=2F12-flash2&alea=yE9u&uuid=6f13a&id=2F15-flash1&alea=eKXN Exos 3, 4, 5 Cours définitions et notation Exo : résolu 1 Heure 2: Exo: exos 7, 8, 9 Cours Représentation graphique 1 Exo : 11, 25, 26 | D2: Q flash : https://coopmaths.fr/alea/?uuid=0b020&id=4C10-7&n=2&d=10&s=true&s2=5&s3=10&cd=1&tip=0&alea=BPIZ&uuid=aa40c&id=2A-C2-2&n=1&d=10&qcm=0&cd=1&tip=0&alea=aGMs&uuid=106e7&id=2A-C2-3&n=1&d=10&qcm=0&cd=1&tip=0&alea=zON1&uuid=83a52&id=1A-C15-9&alea=nlQU | F2: 1 calcul num | G2: 1 calc litt | H2: 1 autre | J2: Ch1 – Généralités sur les fonctions | K2: =IF(B2=J2,"","modifié")
A3: =A2+7 -> 46272 | B3: Ch1 – Généralités sur les fonctions | C3: Q flash : https://coopmaths.fr/alea/?uuid=c96ba&id=1A-C01-7&alea=r5hF&uuid=106e7&id=1A-C09-3&n=1&d=10&qcm=0&cd=1&tip=0&alea=3VSL&uuid=9b4e6&id=2A-R1-1&n=1&d=10&qcm=0&cd=1&tip=0&alea=NjNi&v=diaporama&ds=10000100 Correction 8,9,11. Exo 25(1,2) et 26 Heure 2 Cours : Représentation graphique 2, équation graphique Exos : (19), 28, 29, devoir 30 Exo 27? | E3: Q flash : https://coopmaths.fr/alea/?uuid=fd5c6&id=can2N30-01&alea=cxep&uuid=106e7&id=1A-C09-3&n=1&d=10&qcm=0&cd=1&tip=0&alea=q26b&uuid=2ab24&id=1A-C15-2&n=1&d=10&s=false&s2=false&s4=false&cd=1&tip=0&alea=FMH7 ((Correction exo 41 (skip 49))) Variations Fiche exo, puis si besoin 42, 44 | F3: Relatifs | G3: Distributivité (simple et double) | H3: Proportions/Pourcentages (appliquer un taux d'évolution) | I3: Proportions prépare tableaux croisés | J3: Ch1 – Généralités sur les fonctions | K3: =IF(B3=J3,"","modifié")
A4: =A3+7 -> 46279 | B4: Ch2 – Tableaux croisés et probabilités conditionnelles | C4: Q flash : https://coopmaths.fr/alea/?uuid=0b020&id=4C10-7&n=1&d=10&s=2&s2=1-4&s3=10&cd=1&tip=0&alea=AH8n&uuid=60cc5&id=2L11-3&n=1&d=10&s=1-2-3-4-5-6-7&cd=1&tip=0&alea=caZr&uuid=c9efa&id=2A-E3-1&alea=EYxG Inéquation graphiques Exo 30, 49, 51 | D4: Révisions DS court sur les fonctions | E4: Fiche exo variations | J4: Ch2 – Tableaux croisés et probabilités conditionnelles | K4: =IF(B4=J4,"","modifié")
A5: =A4+7 -> 46286 | B5: Ch2 – Tableaux croisés et probabilités conditionnelles | C5: q flash https://www.mathalea.fr/alea/?uuid=88281&id=2N32-flash1&alea=4VQm&uuid=7f02a&id=1A-C10-11&alea=GGDf&uuid=0f014&id=can1S05&alea=XOxy Activité 1 tableaux + cours P1 | D5: Q flash : https://www.mathalea.fr/alea/?uuid=6575c&id=2N32-1&n=1&d=10&s=4&s2=true&cd=0&tip=0&alea=6XJY&uuid=cb6b3&id=2L21-flash1&alea=Q9HL&uuid=0f014&id=can1S05&alea=ZM9c Cours P1 Exos 1,3 Devoir 4, 5 | E5: Q flash : https://www.mathalea.fr/alea/?uuid=22c4c&id=2N31-flash5&alea=rd17&uuid=c1123&id=2L21-flash3&alea=rd17&uuid=0f014&id=can1S05&alea=KzRl Corrections Exo 2, 6, 8 DM EXO 7 | F5: Fractions | G5: Equations 1er degré | H5: Python for | I5: Equation de deg 1 prépare fct affines | J5: Ch2 – Tableaux croisés et probabilités conditionnelles | K5: =IF(B5=J5,"","modifié")
A6: =A5+7 -> 46293 | B6: Ch2 – Tableaux croisés et probabilités conditionnelles | C6: bloquage | D6: Cours PROBAS Def 1, Def 2, def 3 Exemple dé coloré Def Cardinal Union intersection, évènement contraire Exo 9.1 | E6: Q flash : https://www.mathalea.fr/alea/?uuid=f1208&id=2N30-flash3&alea=QGSR&uuid=7959f&id=2L21-3&n=1&d=10&s=1&cd=1&tip=0&alea=L3gy&uuid=0f014&id=can1S1-05&alea=gexV Recuperer DM Def proba conditionnelle, prop 2 et 3 Exo 9.2, Exo 11 | J6: Ch2 – Tableaux croisés et probabilités conditionnelles | K6: =IF(B6=J6,"","modifié")
A7: =A6+7 -> 46300 | B7: Ch2 – Tableaux croisés et probabilités conditionnelles | C7: correction 2.b act, et ex 9 de la fiche. Q flash : https://www.mathalea.fr/alea/?uuid=247cc&id=1A-C02-1&alea=hpt8&uuid=202d9&id=1A-C10-11&alea=zRgp&uuid=0f014&id=can1S1-05&alea=dr2c. PREVENIR CONTROLE + Flash puis utilisation de tableau Exo 12, exo 10, exo 13 | D7: https://coopmaths.fr/alea/?uuid=7f979&id=1A-C01-1&alea=05CE&uuid=18d0d&id=1A-C09-11&alea=YmBI&uuid=a2ac3&id=2F32-1&alea=msjX&uuid=816b8&id=BP2AutoP1&alea=2IeG Rendre DM Correction 11, 12, Exercice 10 en groupe | E7: Exo 10 | F7: Puissances | G7: Factorisation (facteur commun) | H7: Résolution graph éq/inéq | J7: Ch3 – Fonctions affines | K7: =IF(B7=J7,"","modifié") -> modifié | L7: Le ch. 2 s'est prolongé : correction de l'activité, exercices.
A8: =A7+7 -> 46307 | B8: Ch2 – Tableaux croisés et probabilités conditionnelles (jeudi : évaluation) ; Ch3 – Fonctions affines (vendredi) | C8: EVAL form Tableaux + flash | D8: https://coopmaths.fr/alea/?uuid=7f979&id=1A-C01-1&alea=vMZA&uuid=18d0d&id=1A-C09-11&alea=RB3q&uuid=9d293&id=can2F3-03&alea=Vosg Début du chapitre sur les fonctions affines Partire 1, exercices 1 et 2. | E8: https://coopmaths.fr/alea/?uuid=7f979&id=1A-C01-1&alea=9wyF&uuid=18d0d&id=1A-C09-11&alea=pwyJ&uuid=61271&id=can2F3-05&alea=dms0 Cours 2 : représentation graphique (représenter) Exo 3 Cours 2/ représentation graphique (lire) Exo 4 | J8: Ch3 – Fonctions affines | K8: =IF(B8=J8,"","modifié") -> modifié | L8: Jeudi : évaluation formative sur les tableaux (ch. 2). Vendredi 16/10 : début du ch. 3.
A9: =A8+7 -> 46314 | B9: Vacances | J9: Vacances | K9: =IF(B9=J9,"","modifié")
A10: =A9+7 -> 46321 | B10: Vacances | J10: Vacances | K10: =IF(B10=J10,"","modifié")
A11: =A10+7 -> 46328 | B11: Ch3 – Fonctions affines | C11: Ch3 S1 – Reprise en douceur : rappel (ex. 2), puis page 3 du cours depuis le début (droite y = ax + b, méthode « Tracer une droite »). Ex. 3. Devoir : finir l'ex. 3. | D11: Ch3 S2 – Cours fin partie 2 : lire l'équation réduite d'une droite (p. 4). Ex. 4 (d1 à d4). | E11: Ch3 S3 – Cours partie 3 : coefficient directeur, fonction affine à partir de deux points (p. 4-5). Ex. 5, ex. 6 (1, 2). Devoir : ex. 6 (3), ex. 9. | F11: Comparaison nombre | G11: Signe fonctions affines | H11: Tableaux de sgn graphiquement | I11: Faire du tableur, faire du Python | J11: Ch4 – Généralités sur les suites | K11: =IF(B11=J11,"","modifié") -> modifié | L11: Reprise du ch. 3 en douceur (page 3 reprise) : les chapitres suivants sont décalés d'une semaine.
A12: =A11+7 -> 46335 | B12: Ch3 – Fonctions affines (jeudi) ; Ch4 – Généralités sur les suites (vendredi) | C12: Ch3 S4 – Cours parties 4 et 5 : sens de variation, tableau de signes (p. 5-6) ; bilan. Correction ex. 9, ex. 7, ex. 8. Devoir maison : ex. 10 et 11. | D12: Ch4 S1 – Activité 1 : la crèche (u(n) = 20 + 6n, budget ×1,1, nuage de points). Bilan à trous. Correction des ex. 10-11 du ch. 3 en début d'heure. | E12: Ch4 S2 – Cours 1.1-1.2 : définition, notation u_n, formule explicite. Ex. 1, ex. 2 (1, 2). Devoir : ex. 2 (3, 4), ex. 3 (1 à 3). | I12: Signe fct affines prépare fcts du second degré | J12: Ch4 – Généralités sur les suites | K12: =IF(B12=J12,"","modifié") -> modifié | L12: Le ch. 4 passe à 8 séances : synthèse (ex. 17) en devoir.
A13: =A12+7 -> 46342 | B13: Ch4 – Généralités sur les suites | C13: Ch4 S3 – Cours 1.3-1.4 : relation de récurrence, comparer les deux modes. Ex. 4 (1, 2), ex. 5. Devoir : ex. 4 (3, 4), ex. 6. | D13: Ch4 S4 – Cours 2 : représentation graphique. Ex. 8, ex. 9. Devoir : ex. 10, ex. 7. | E13: Ch4 S5 – Cours 3 : modéliser. Ex. 11 (1 à 3), ex. 12 (1, 2). Devoir : ex. 11 (4), ex. 12 (3). | F13: Racines carrées | G13: Equations produit nul | H13: Coeff multiplicateur/taux d'évolution (évolutions successives) | J13: Ch4 – Généralités sur les suites | K13: =IF(B13=J13,"","modifié")
A14: =A13+7 -> 46349 | B14: Ch4 – Généralités sur les suites | C14: Ch4 S6 – Cours 4 : sens de variation. Ex. 13, ex. 14 (1 à 4). Devoir : ex. 14 (5, 6). | D14: Ch4 S7 – Cours 5 : tableur projeté (seuil) puis Python. Ex. 15, ex. 16 (1, 2). Devoir : ex. 16 (3, 4), ex. 17 (synthèse). | E14: Ch4 S8 – Contrôle formatif (sujets A et B). | J14: Ch5 – Fonctions du second degré | K14: =IF(B14=J14,"","modifié") -> modifié | L14: Contrôle formatif du ch. 4 en fin de semaine.
A15: =A14+7 -> 46356 | B15: Ch5 – Fonctions du second degré | C15: Ch5 S1 – Activité 1 : le saut du dauphin, f(t) = a(t − t1)(t − t2). Devoir : finir le développement de f(t). | D15: Ch5 S2 – Forme factorisée : racines, vérifier une racine, tableau de signes. Devoir : une étude de signe. | E15: Ch5 S3 – Allure (GeoGebra : effet de a), axe au milieu des racines, sommet, variations. Devoir : étude complète d'une parabole tournée vers le bas. | F15: Ordre de grandeur | G15: Développer (a+b)² et (a-b)² avec ou sans identités remarquables | H15: Probabilités | I15: Plus d'étude de fonctions de degré 3 | J15: Ch5 – Fonctions du second degré | K15: =IF(B15=J15,"","modifié")
A16: =A15+7 -> 46363 | B16: Ch5 – Fonctions du second degré | C16: Ch5 S4 – Forme développée : développer, f(0) = c, axe en résolvant f(x) = c, sommet. Devoir : développer et vérifier. | D16: Ch5 S5 – Paraboles ax² et ax² + c (GeoGebra : effet de c) ; associer parabole et expression. Devoir : tracer une parabole ax² + c. | E16: Ch5 S6 – Factoriser connaissant une racine, puis étudier le signe. Devoir : une factorisation. | J16: Ch5 – Fonctions du second degré | K16: =IF(B16=J16,"","modifié")
A17: =A16+7 -> 46370 | B17: Ch5 – Fonctions du second degré | C17: Ch5 S7 – Résolution graphique, balayage (table de la calculatrice), problème en contexte. Devoir : finir le problème. | D17: Ch5 S8 – Synthèse. Devoir : réviser le savoir-faire. | E17: Ch5 S9 – Contrôle formatif (sujets A et B). | F17: Conversions | G17: Suites | H17: Pourcentages/coeff multiplicateur | I17: ajout de l'indépendance et formule des probas totales | J17: Ch6 – Arbres de probabilités, épreuve de Bernoulli | K17: =IF(B17=J17,"","modifié") -> modifié
A18: =A17+7 -> 46377 | B18: Vacances | J18: Vacances | K18: =IF(B18=J18,"","modifié")
A19: =A18+7 -> 46384 | B19: Vacances | J19: Vacances | K19: =IF(B19=J19,"","modifié")
A20: =A19+7 -> 46391 | B20: Ch6 – Arbres de probabilités, épreuve de Bernoulli | F20: Conversions | G20: Suites | H20: Pourcentages/coeff multiplicateur | I20: Suites prépare chap suivant tout comme coeff multiplicateur (suites géom) | J20: Ch6 – Arbres de probabilités, épreuve de Bernoulli | K20: =IF(B20=J20,"","modifié")
A21: =A20+7 -> 46398 | B21: Ch6 – Arbres de probabilités, épreuve de Bernoulli | F21: Stats 1 (moyenne, médiane, quartiles) | G21: Isoler variable | H21: Python while | J21: Ch6 – Arbres de probabilités, épreuve de Bernoulli | K21: =IF(B21=J21,"","modifié")
A22: =A21+7 -> 46405 | B22: Ch6 – Arbres de probabilités, épreuve de Bernoulli | I22: ajout forme explicite, faire du tableur, faire du Python | J22: Ch7 – Suites arithmétiques et géométriques | K22: =IF(B22=J22,"","modifié") -> modifié
A23: =A22+7 -> 46412 | B23: Ch7 – Suites arithmétiques et géométriques | F23: Fractions | G23: Inéquations | H23: Equations de droite (lecture, calcul coeff) | I23: Equations de droites prépare tangente | J23: Ch7 – Suites arithmétiques et géométriques | K23: =IF(B23=J23,"","modifié")
A24: =A23+7 -> 46419 | B24: Ch7 – Suites arithmétiques et géométriques | J24: Ch7 – Suites arithmétiques et géométriques | K24: =IF(B24=J24,"","modifié")
A25: =A24+7 -> 46426 | B25: Vacances | J25: Vacances | K25: =IF(B25=J25,"","modifié")
A26: =A25+7 -> 46433 | B26: Vacances | J26: Vacances | K26: =IF(B26=J26,"","modifié")
A27: =A26+7 -> 46440 | B27: Ch7 – Suites arithmétiques et géométriques | F27: App num d'une formule | G27: Identités rem | H27: Stats 2 (Lire et exploiter un graphique : histo, diagramme barre et circulaire) | I27: Lien avec les sécantes (utiliser Géogébra) | J27: Ch8 – Dérivation locale, tangente, dérivées usuelles | K27: =IF(B27=J27,"","modifié") -> modifié | L27: Ch. 7 à cheval sur les vacances d'hiver.
A28: =A27+7 -> 46447 | B28: Ch8 – Dérivation locale, tangente, dérivées usuelles | J28: Ch8 – Dérivation locale, tangente, dérivées usuelles | K28: =IF(B28=J28,"","modifié")
A29: =A28+7 -> 46454 | B29: Ch8 – Dérivation locale, tangente, dérivées usuelles | F29: Proportions | G29: Signe fonction 2nd degré | H29: Dérivation | I29: Dérivation et signe fct degré 2 préparent chap suivant | J29: Ch8 – Dérivation locale, tangente, dérivées usuelles | K29: =IF(B29=J29,"","modifié")
A30: =A29+7 -> 46461 | B30: Ch8 – Dérivation locale, tangente, dérivées usuelles | J30: Ch9 – Variables aléatoires, loi de Bernoulli | K30: =IF(B30=J30,"","modifié") -> modifié
A31: =A30+7 -> 46468 | B31: Ch9 – Variables aléatoires, loi de Bernoulli | F31: Evolutions | G31: Equations produit nul | H31: Tableaux de variations graphiquement | J31: Ch9 – Variables aléatoires, loi de Bernoulli | K31: =IF(B31=J31,"","modifié")
A32: =A31+7 -> 46475 | B32: Ch9 – Variables aléatoires, loi de Bernoulli | J32: Ch10 – Applications de la dérivation | K32: =IF(B32=J32,"","modifié") -> modifié
A33: =A32+7 -> 46482 | B33: Vacances | J33: Vacances | K33: =IF(B33=J33,"","modifié")
A34: =A33+7 -> 46489 | B34: Vacances | J34: Vacances | K34: =IF(B34=J34,"","modifié")
A35: =A34+7 -> 46496 | B35: Ch10 – Applications de la dérivation | F35: Puissances | G35: Suites | H35: Stats 3 (Diagramme en boite) | J35: Ch10 – Applications de la dérivation | K35: =IF(B35=J35,"","modifié")
A36: =A35+7 -> 46503 | B36: Ch10 – Applications de la dérivation | J36: Ch11 – Séries statistiques à deux variables | K36: =IF(B36=J36,"","modifié") -> modifié
A37: =A36+7 -> 46510 | B37: Ch11 – Séries statistiques à deux variables | F37: Fractions | G37: Equations : x²=a et a/x=b | H37: Pourcentages | J37: Ch11 – Séries statistiques à deux variables | K37: =IF(B37=J37,"","modifié")
A38: =A37+7 -> 46517 | B38: Ch11 – Séries statistiques à deux variables | J38: Ch12 – Listes en Python (1 h) | K38: =IF(B38=J38,"","modifié") -> modifié
A39: =A38+7 -> 46524 | B39: Ch12 – Listes en Python (1 h) ; Révisions – automatismes papier type bac | F39: Automatismes papiers type bac | J39: Révisions – automatismes papier type bac | K39: =IF(B39=J39,"","modifié") -> modifié | L39: Révisions réduites de 3 à 2 semaines (+ 2 h cette semaine).
A40: =A39+7 -> 46531 | B40: Révisions – automatismes papier type bac | J40: Révisions – automatismes papier type bac | K40: =IF(B40=J40,"","modifié")
...

Sheet Chapitres
A1: Chapitres : périodes avant / après
A2: Dates = lundi de la première et de la dernière semaine. Décalage et nombre de semaines calculés par formules à partir de l'onglet Séances (une semaine partagée entre deux chapitres compte pour les deux).
A4: Code | B4: Chapitre | C4: Début avant | D4: Fin avant | E4: Début après | F4: Fin après | G4: Décalage du début (semaines de calendrier, vacances comprises) | H4: Semaines avant | I4: Semaines après
A5: Ch1 | B5: Généralités sur les fonctions | C5: 46265 | D5: 46272 | E5: 46265 | F5: 46272 | G5: =(E5-C5)/7 -> 0 | H5: =COUNTIF(Séances!$J$2:$J$42,"*"&A5&" –*") -> 2 | I5: =COUNTIF(Séances!$B$2:$B$42,"*"&A5&" –*") -> 2
A6: Ch2 | B6: Tableaux croisés et probabilités conditionnelles | C6: 46279 | D6: 46293 | E6: 46279 | F6: 46307 | G6: =(E6-C6)/7 -> 0 | H6: =COUNTIF(Séances!$J$2:$J$42,"*"&A6&" –*") -> 3 | I6: =COUNTIF(Séances!$B$2:$B$42,"*"&A6&" –*") -> 5
A7: Ch3 | B7: Fonctions affines | C7: 46300 | D7: 46307 | E7: 46307 | F7: 46335 | G7: =(E7-C7)/7 -> 1 | H7: =COUNTIF(Séances!$J$2:$J$42,"*"&A7&" –*") -> 2 | I7: =COUNTIF(Séances!$B$2:$B$42,"*"&A7&" –*") -> 3
A8: Ch4 | B8: Généralités sur les suites | C8: 46328 | D8: 46342 | E8: 46335 | F8: 46349 | G8: =(E8-C8)/7 -> 1 | H8: =COUNTIF(Séances!$J$2:$J$42,"*"&A8&" –*") -> 3 | I8: =COUNTIF(Séances!$B$2:$B$42,"*"&A8&" –*") -> 3
A9: Ch5 | B9: Fonctions du second degré | C9: 46349 | D9: 46363 | E9: 46356 | F9: 46370 | G9: =(E9-C9)/7 -> 1 | H9: =COUNTIF(Séances!$J$2:$J$42,"*"&A9&" –*") -> 3 | I9: =COUNTIF(Séances!$B$2:$B$42,"*"&A9&" –*") -> 3
A10: Ch6 | B10: Arbres de probabilités, épreuve de Bernoulli | C10: 46370 | D10: 46398 | E10: 46391 | F10: 46405 | G10: =(E10-C10)/7 -> 3 | H10: =COUNTIF(Séances!$J$2:$J$42,"*"&A10&" –*") -> 3 | I10: =COUNTIF(Séances!$B$2:$B$42,"*"&A10&" –*") -> 3
A11: Ch7 | B11: Suites arithmétiques et géométriques | C11: 46405 | D11: 46419 | E11: 46412 | F11: 46440 | G11: =(E11-C11)/7 -> 1 | H11: =COUNTIF(Séances!$J$2:$J$42,"*"&A11&" –*") -> 3 | I11: =COUNTIF(Séances!$B$2:$B$42,"*"&A11&" –*") -> 3
A12: Ch8 | B12: Dérivation locale, tangente, dérivées usuelles | C12: 46440 | D12: 46454 | E12: 46447 | F12: 46461 | G12: =(E12-C12)/7 -> 1 | H12: =COUNTIF(Séances!$J$2:$J$42,"*"&A12&" –*") -> 3 | I12: =COUNTIF(Séances!$B$2:$B$42,"*"&A12&" –*") -> 3
A13: Ch9 | B13: Variables aléatoires, loi de Bernoulli | C13: 46461 | D13: 46468 | E13: 46468 | F13: 46475 | G13: =(E13-C13)/7 -> 1 | H13: =COUNTIF(Séances!$J$2:$J$42,"*"&A13&" –*") -> 2 | I13: =COUNTIF(Séances!$B$2:$B$42,"*"&A13&" –*") -> 2
A14: Ch10 | B14: Applications de la dérivation | C14: 46475 | D14: 46496 | E14: 46496 | F14: 46503 | G14: =(E14-C14)/7 -> 3 | H14: =COUNTIF(Séances!$J$2:$J$42,"*"&A14&" –*") -> 2 | I14: =COUNTIF(Séances!$B$2:$B$42,"*"&A14&" –*") -> 2
A15: Ch11 | B15: Séries statistiques à deux variables | C15: 46503 | D15: 46510 | E15: 46510 | F15: 46517 | G15: =(E15-C15)/7 -> 1 | H15: =COUNTIF(Séances!$J$2:$J$42,"*"&A15&" –*") -> 2 | I15: =COUNTIF(Séances!$B$2:$B$42,"*"&A15&" –*") -> 2
A16: Ch12 | B16: Listes en Python (1 h) | C16: 46517 | D16: 46517 | E16: 46524 | F16: 46524 | G16: =(E16-C16)/7 -> 1 | H16: =COUNTIF(Séances!$J$2:$J$42,"*"&A16&" –*") -> 1 | I16: =COUNTIF(Séances!$B$2:$B$42,"*"&A16&" –*") -> 1
A17: Révisions | B17: automatismes papier type bac | C17: 46524 | D17: 46538 | E17: 46524 | F17: 46538 | G17: =(E17-C17)/7 -> 0 | H17: =COUNTIF(Séances!$J$2:$J$42,"*"&A17&" –*") -> 3 | I17: =COUNTIF(Séances!$B$2:$B$42,"*"&A17&" –*") -> 3
